const authService = require("../services/Auth.service");

// Register New User
exports.register = async function (req, res) {
  // req validation would be handled here - We're just assuming the request is properly formed
  // fine for a proof-of-concept, terrible in practice
  const newUserInput = req.body;

  let newUser;
  try {
    newUser = await authService.registerUser(newUserInput);
  } catch (err) {
    console.log(err);
    if (err.message == "EXISTING_USER_ERROR") {
      return res.status("422").json({ message: "User already exists" });
      // If you don't include the above return, the code will continue executing
      // and hit the throw new Error("REGISTER_USER_ERROR") below, causing our app to crash
    }
    throw new Error(err);
  }

  res.json(newUser);
};

exports.login = async function (req, res) {
  const userInput = req.body;

  let existingUser;
  try {
    existingUser = await authService.loginUser(userInput);
  } catch (err) {
    console.log(err);
    if (err.message == "INVALID_LOGIN_CREDENTIALS") {
      return res
        .status("401")
        .json({ message: "Invalid username or password" });
    }
    throw new Error(err);
  }

  res.json(existingUser);
};

exports.protected = async function (req, res) {
  console.log("Reached Protected Route")

  res.send("/post")
};
